Workbook

Sheet UnitTenant Mix
A1: Owner | B1: Name | C1: Space | D1: Width | E1: Length | F1: Height | G1: Rate (Cost Price) | H1: Web Rate (not there on app right now) | I1: Space Size [width * length] | J1: Space Category | K1: Door Width | L1: Door Height display in application as w*h when available in database) | M1: Amenities | N1: Sq. Ft. | O1: Floor (application does not allow non numeric values, but can be entered through backend) | P1: First Name | Q1: Last Name | R1: Middle Name | S1: Account Code | T1: Address | U1: City | V1: State | W1: ZIP | X1: Country | Y1: email | Z1: Primary Phone | AA1: Secondary Phone | AB1: Tertiary Phone | AC1: Access Code | AD1: DOB | AE1: Active Military | AF1: DL Id | AG1: DL State | AH1: DL City | AI1: DL Exp Date | AJ1: Rent | AK1: Last Rent Change Date | AL1: Move In Date | AM1: Move Out Date | AN1: Paid Date | AO1: Bill Day | AP1: Paid Through Date | AQ1: Alt First Name | AR1: Alt Last Name | AS1: Alt Middle Name | AT1: Alt Address | AU1: Alt City | AV1: Alt State | AW1: Alt ZIP | AX1: Alt Email | AY1: Alt Home Phone | AZ1: Alt Work Phone | BA1: Alt Cell Phone | BB1: Security Deposit (prods defined and on MSR but not on application yet) | BC1: Security Deposit Balance | BD1: Rent Balance | BE1: Fees Balance | BF1: Protection/Insurance Balance | BG1: Merchandise Balance | BH1: Late Fees Balance | BI1: Lien Fees Balance | BJ1: Tax Balance | BK1: Prepaid Rent | BL1: Prepaid Additional Rent/ Premium | BM1: Prepaid Tax | BN1: Protection/Insurance Provider | BO1: Protection/Insurance Coverage | BP1: Additional Rent/Premium | BQ1: Delinquency Status | BR1: Lien Status | BS1: Lien Posted Date (when lien was initiated) | BT1: Promotion | BU1: Promotion Type | BV1: Promotion Value | BW1: Promotion Start | BX1: Promotion Length | BY1: Discount | BZ1: Discount Type | CA1: Discount Value
A2: [Storage Provider Name] | B2: [Facility/Property Name] | C2: [Space Number] | D2: [Width] | E2: [Length] | F2: [Height] | G2: [Price] | H2: [Price Displayed on Web] | I2: [5 x 10, 5 x 5] | J2: [Interior, Drive Up, Climate Controled] | K2: [Width] | L2: [Height] | M2: [Cabnits, Shelves, Alarm, Light etc.] | O2: [Ground, 1st, 1 etc.] | P2: [Tenant First Name] | Q2: [Tenant Last Name] | R2: [Tenant Middle Name] | S2: [For Unique Tenant Identification] | AC2: [Gate Access Code] | AD2: [Date of Birth] | AE2: [True/False] | AF2: [Driving License ID] | AG2: [Driving License State] | AH2: [Driving License City] | AI2: [Driving License Expiry Date] | AJ2: [Rent Amount] | BQ2: [True/False] | BT2: [Promotion Name] | BU2: [Promotion Fixed/Percentage/Dollar] | BV2: [Amount] | BW2: [Promotion Start Date] | BX2: [Promotion Length Months] | BY2: [Discount Name] | BZ2: [Discount Fixed/Percentage/Dollar] | CA2: [Amount]
A3: Do not fill out | B3: Do not fill out | C3: Numeric or alpha numeric (i.e. 101, A101, 101C) | D3: ex. 10 or 10.5 | E3: ex. 10 or 10.5 | F3: ex. 10 or 10.5 (for parking spaces height can be 0) | G3: Sell Rate - Can include decimals | H3: We currently do not have separate rates for Website. This field would be a copy of Column G - Rate (or leave blank) until this functionality is implemented on HB | I3: In the format [width] x [length], can include decimals | N3: This should be a calculated product of width * length | S3: Make sure the First name Last name, Email, Phone Number, Account Code and Addresses (both Primary and Alternate) match for the tenants with same First name last Name and Email Addresses | T3: Includes both Address line 1 and 2. Ex: 4920 Campus Dr, Suite B | V3: This should be in "CA" format instead of "California". Should use address verification migration package to validate this | Z3: No formatting, entered as 1234567980 | AA3: No formatting, entered as 1234567980 | AB3: No formatting, entered as 1234567980 | AD3: Format mm/dd/yyyy | AE3: FALSE | AG3: Format should be "CA" instead of "California" | AI3: Format mm/yyyy | AK3: Format mm/dd/yyyy | AL3: Format mm/dd/yyyy | AM3: Format mm/dd/yyyy | AN3: Format mm/dd/yyyy | AO3: number 1-30/31, when the tenant is billed | AP3: Format mm/dd/yyyy | BD3: Required if a tenant is Past Due | BE3: Required if a tenant is Past Due and has fees other than Late Fees | BF3: Required if a tenant has past due for Coverage | BG3: Required if a tenant has past due for Merchandise | BH3: Required if a tenant is Past Due and has Late Fee | BI3: Required if a tenant is Past Due and has Lien Fee | BJ3: Required if a tenant is Past Due and has Tax Balance | BK3: Required if a tenant has Prepaid Rent | BL3: Required if a tenant has Prepaid Coverage | BM3: Required if a tenant has Prepaid Tax | BN3: Required if a tenant has a Coverage | BO3: Required if a tenant has a Coverage | BP3: Required if a tenant has a Coverage | BQ3: Do not fill out, will be based on outstanding balances | BR3: Do not fill out, will be based on paid thru date | BS3: Do not fill out | BY3: NOTE: Discounts are applied to the lifetime of the tenants (no end date)
C4: no special charaters | D4: number between 0 and 100 | E4: number between 0 and 101 | F4: number between 0 and 102 | G4: Only number AND no special charaters | H4: hidden | I4: auto | J4: no validation | K4: only numbers no special charaters | L4: only numbers no special charaters | M4: hide | O4: no special charaters | P4: no validation | Q4: no validation | R4: no validation | S4: protect range | T4: no validtion | U4: no special charaters besides dash | V4: only text | W4: only number and dash no special charaters | X4: default USA using if stament | Y4: is valid email | Z4: 4175228858 | AA4: 417-522-8858234 | AC4: no special charaters no letter | AD4: is. a valid date reject input | AE4: formula for only true or false | AF4: no special charaters | AJ4: only numbers from 0 to 10,000
AE5: TRUE
AE6: TRUE
AE7: FALSE
AE8: FALSE
M9: ` | AE9: FALSE
AE10: FALSE
AE11: FALSE
AE12: FALSE
AE13: FALSE
AE14: FALSE
AE15: FALSE
AE16: FALSE
AE17: FALSE
AE18: FALSE
AE19: FALSE
AE20: FALSE
AE21: FALSE
... AE1000: FALSE

Sheet Instructions
A1: Instructions:
B2: When pasting please paste with values. (Windows: Ctrl+Shift+V or Mac: Command+Shift+V)
A4: Tabs | B4: Instructions
A5: Space Mix | B5: All yellow columns are required. Grey columns are auto filled. White columns are optional. | G5: Required | H5: Not Required | I5: Auto Filled
A6: Tenant Info | B6: Yellow columns will prepopulate with the data that is filled in on the space mix tab. Green columns are required. White Coulmns are optional. | G6: Pre-populated | H6: Required | I6: Not Required | J6: Auto Filled
A7: Tenant Payment Info | B7: Yellow and green columns will prepopulate from Space Mix tab and Tenant Info tab. Blue columns are required. White columns are optional | G7: Pre-populated | H7: Pre-populated | I7: Required | J7: Not Required | K7: Auto Filled | L7: Required
A8: Promotions/Discounts | B8: This tab is not required unless a tenant has a recurring discount or promotion. | G8: Pre-populated | H8: Pre-populated | I8: Required
A9: Final Sheet (Ony View) | B9: All data from each tab will fill in and allows you to view all data entry on one sheet. This is a protected sheet, so you will only be able to view but not edit. If you want to edit something please go to the respective tab and make the change.
A10: Description Format Info | B10: You can find descriptions and format of each column of each tab of the spreadsheet
A11: MIG Team Final Sheet | B11: Pleas don't fill out. For our internal team only

Sheet Description Format Info
A1: Name of Column | B1: Description | C1: Format | D1: Required/Optional | E1: Notes
A2: Spaces
A3: Space | B3: This is the identification number assigned to the space. It can consist of either a number or a combination of letters and numbers. | C3: 101 or A-101 | D3: Required
A4: Width | B4: The width of the space refers to the measurement from one side to the other. It can be a whole number or a number with decimal points. | C4: 10 or 10.5 | D4: Required
A5: Length | B5: The length of the space is the measurement from one end to the other. Like the width, it can also be a whole number or a number with decimal points. | C5: 10 or 10.5 | D5: Required
A6: Height | B6: The height of the space represents the vertical measurement. It can be a whole number or a number with decimal points. For parking spaces, the height can be entered as 0, indicating a flat surface. | C6: 10 or 10.5 | D6: Required
A7: Rate (Cost Price) | B7: The Rate or Cost Price of the space is the price at which the space is sold to customers. This value can be represented as either a whole number or a number with decimal points, depending on the specific pricing of the space. It reflects the monetary amount that customers need to pay to acquire the space. | C7: 100 or 48.5 | D7: Required
A8: Web Rate (not there on app right now) | B8: The Web Rate refers to the price at which the space is advertised on the website. This value can be expressed as either a whole number or a number with decimal points, depending on the specific pricing. It is the price that customers will see and consider when making a decision to book the space through the website. NOTE: For Hummingbird currently the Rate and Web Rate would be the same as we do not have differential pricing. | C8: 100 or 48.5 | D8: Required
A9: Space Size | B9: The size of the space expressed in [width] * [length] format. This is a calculated value. | C9: 10 x 10 or 10.5 x 10.5 | D9: Calculated Value
A10: Space Category | B10: The category of the space. | C10: Interior | D10: Required
A11: Door Width | B11: The width of the door. This can be a number or a decimal. | C11: 8 or 8.75 | D11: Optional
A12: Door Height | B12: The height of the door. This can be a number or a decimal. | C12: 8 or 8.75 | D12: Optional
A13: Amenities | B13: The amenities of the space. Amenities are entered as comma separated. This is currently are now handled by Rate Management | C13: Tall Door, Lights in Unit | D13: Do not enter
A14: Sq. Ft. | B14: The square footage of the space is a calculated value obtained by multiplying the width and length of the space. This value represents the total area covered by the space in square feet. | C14: 100 or 110.25 | D14: Calculated Value
A15: Floor | B15: The floor indicates the specific level or storey where the space is situated within a building or a facility. For example, if the space is located on the ground level, it would be indicated as "0." If it is on the first level above the ground floor, it would be labeled as "1" and so on. NOTE: Please indicate all Floors in a numeric value | C15: 1 or 0 | D15: Required | E15: This would be a requirement when Property Map feature is in production
A17: Tenants
A18: First Name | B18: The first name of the tenant occupying that space. | C18: Joe | D18: Required | E18: Ensure that the First Name, Last Name, Email, Phone Number, Account Code, and Addresses (both Primary and Alternate) are consistent for tenants who have multiple spaces linked to their account. This means verifying and ensuring that all their details are the same across all the spaces they occupy. By doing this, we can avoid any discrepancies and maintain accurate and uniform information for tenants who have multiple spaces under their account. This helps in organizing tenant data and streamlining administrative processes for efficient tenant management.
A19: Last Name | B19: The last name of the tenant occupying that space. | C19: Doe | D19: Required
A20: Middle Name | B20: The middle name of the tenant occupying that space | C20: Yoda | D20: Optional
A21: Account Code | B21: The Account Code is primarily used when there are multiple spaces associated with one tenant. In such cases, the tenant assigns the same number next to each of those spaces to create unique identifiers. For instance, if Tenant Yoda has both Space 101 and Space 102, they would use the Account Code "1" for both spaces. Similarly, if Tenant Darth has Space 103, they would use the Account Code "2" for that particular space. By using Account Codes, it becomes easier to link and manage multiple spaces that belong to the same tenant. This system ensures clear identification and organization, allowing for efficient record-keeping and invoicing processes. It helps property managers or administrators easily track and associate specific spaces with their corresponding tenants, streamlining administrative tasks and facilitating accurate billing and documentation. Space Account Code 101 1 102 1 103 2 | C21: 1 | D21: Auto Generated based on gate access code
A22: Address | B22: The address of the tenant occupying that space. This field includes both Address 1 and Address 2 of the tenant. | C22: 4920 Campus Dr, Suite B | D22: Required
A23: City | B23: The city in which the tenant is located at. | C23: Irvine | D23: Required
A24: State | B24: The abbreviation of the state in which the tenant is located at. | C24: CA | D24: Required
A25: ZIP | B25: The zipcode of the address where the tenant is located at. | C25: 90007 or HAP123 | D25: Required
A26: Country | B26: The country where the tenant is located at. We currently only support USA. | C26: USA | D26: Required
A27: Email | B27: The email address of the tenant. | C27: abc@gmail.com | D27: Required
A28: Cell Phone | B28: The cell phone number of the tenant. Ensure to enter just the phone number without the country code. For example, if your phone number is +1 (213) 111-0000, the phone number field should be filled in as 2131110000 (no formatting needed). | C28: 2131110000 | D28: Required | E28: At least one phone number is needed which would then become the Primary Phone Number
A29: Home Phone | B29: The home phone number of the tenant. Ensure to enter just the phone number without the country code. For example, if your phone number is +1 (213) 111-0000, the phone number field should be filled in as 2131110000 (no formatting needed). | C29: 2131110000 | D29: Optional
A30: Work Phone | B30: The work phone number of the tenant. Ensure to enter just the phone number without the country code. For example, if your phone number is +1 (213) 111-0000, the phone number field should be filled in as 2131110000 (no formatting needed). | C30: 2131110000 | D30: Optional
A31: Access Code | B31: The Access Code is a unique numeric code assigned to each tenant for secure access purposes. It can be either a custom code or the last 5 digits of the tenant's phone number. Access codes are always numeric and can range from 1 to 9 digits in length. This code is used to authenticate the tenant's identity and grant them access to specific areas or facilities. | C31: 12345 | D31: Required | E31: can use the last 4 digits of their phone number as access code
A32: DOB | B32: The date of birth of the tenant. This should be in the format MM/DD/YYYY. | C32: 09/11/2015 | D32: Optional
A33: Active Military | B33: If the tenant is in active military, enter Yes. Else enter No. | C33: Yes or No | D33: Optional
A34: DL Id | B34: The Driver's License number of the tenant. | C34: DL12345 | D34: Optional
A35: DL State | B35: The abbreviated state in which the Driver's License was issued for the tenant. | C35: CA | D35: Optional
A36: DL City | B36: The city in which the Driver's License was issued for the tenant. | C36: Irvine | D36: Optional
A37: DL Exp Date | B37: The expiration date of the Driver's License | C37: 08/2020 | D37: Optional
A38: Rent | B38: The rent the tenant is currently being charged for the space. | C38: 100 or 100.05 | D38: Required
A39: Last Rent Change Date | B39: The date when the last rent change was done | C39: 01/10/2020 | D39: Optional | E39: NOTE: If the operator does not provide this information, the last rent change would be calculated from their move in date on HB
A40: Move In Date | B40: The date the tenant moved into the space. This should be in the format MM/DD/YYYY. | C40: 01/01/2020 | D40: Required
A41: Move Out Date | B41: This should only be entered if an existing tenant is scheduled to move out. This should be in the format MM/DD/YYYY. | C41: 01/10/2020 | D41: Optional
...

Sheet Space mix
A1: Space | C1: Space Type | D1: Width | E1: Length | F1: Height | G1: Rate | H1: Space Category | I1: Floor | J1: Door Width | K1: Door Height | L1: Space Size | M1: Sq. Ft.
A2: 101 or A-101 | B2: Occupied or Vacant | C2: Storage or Parking | D2: 10 or 10.5 | E2: 10 or 10.5 | F2: 10 or 10.5 | G2: 100 or 48.5 | H2: Drive Up or Climate Controled | I2: 0, 1st, 1 | J2: 8 or 8.75 | K2: 8 or 8.75 | L2: [5 x 10]
L3: ="["&D3&" X "&E3&"]" | M3: =D3*E3

Sheet Tenant Info
A1: ='Space mix'!A1 -> Space | B1: ='Space mix'!B1 | C1: First Name | D1: Last Name | E1: Middle Name | F1: Rent | G1: Move In Date | H1: Active Military | I1: Account Code | J1: Address | K1: City | L1: State | M1: ZIP | N1: Country | O1: Email | P1: Cell Phone | Q1: Home Phone | R1: Work Phone | S1: Access Code | T1: DL Id | U1: DL State | V1: DL City | W1: DL Exp Date | X1: Alt First Name | Y1: Alt Last Name | Z1: Alt Middle Name | AA1: Alt Address | AB1: Alt City | AC1: Alt State | AD1: Alt ZIP | AE1: Alt Email | AF1: Alt Home Phone | AG1: Alt Work Phone | AH1: Alt Cell Phone
A2: ='Space mix'!A2 -> 101 or A-101 | B2: ='Space mix'!B2 -> Occupied or Vacant | C2: Joe | D2: Doe | E2: Yoda | F2: 100 or 100.05 | G2: MM/DD/YYYY | H2: [True/False] | I2: [For Unique Tenant Identification] | J2: 4920 Campus Dr, Suite B | K2: Newport Beach | L2: CA | M2: 90007 or HAP123 | N2: USA | O2: abc@gmail.com | P2: 2131110000 (no formatting) | Q2: 2131110001 (no formatting) | R2: 2131110002 (no formatting) | S2: 12345 (btwn 1-9 digits) | T2: DL12345 | U2: CA | V2: Newport Beach | W2: MM/YYYY | X2: Luke | Y2: Skywalker | Z2: Chewbacca | AA2: 4920 Campus Dr, Suite B | AB2: Irvine | AC2: CA | AD2: 90007 or HAP123 | AE2: abc@gmail.com | AF2: 2131110000 (no formatting) | AG2: 2131110000 (no formatting) | AH2: 2131110000 (no formatting)
A3: ='Space mix'!A3 | B3: ='Space mix'!B3 | F3: =XLOOKUP(A3,'Space mix'!$A$3:$A$832,'Space mix'!$G$3:$G$832)
A4: ='Space mix'!A4 | B4: ='Space mix'!B4 | F4: =XLOOKUP(A4,'Space mix'!$A$3:$A$832,'Space mix'!$G$3:$G$832)
A5: ='Space mix'!A5 | B5: ='Space mix'!B5 | F5: =XLOOKUP(A5,'Space mix'!$A$3:$A$832,'Space mix'!$G$3:$G$832)
A6: ='Space mix'!A6 | B6: ='Space mix'!B6 | F6: =XLOOKUP(A6,'Space mix'!$A$3:$A$832,'Space mix'!$G$3:$G$832)
A7: ='Space mix'!A7 | B7: ='Space mix'!B7 | F7: =XLOOKUP(A7,'Space mix'!$A$3:$A$832,'Space mix'!$G$3:$G$832)
A8: ='Space mix'!A8 | B8: ='Space mix'!B8 | F8: =XLOOKUP(A8,'Space mix'!$A$3:$A$832,'Space mix'!$G$3:$G$832)
A9: ='Space mix'!A9 | B9: ='Space mix'!B9 | F9: =XLOOKUP(A9,'Space mix'!$A$3:$A$832,'Space mix'!$G$3:$G$832)
A10: ='Space mix'!A10 | B10: ='Space mix'!B10 | F10: =XLOOKUP(A10,'Space mix'!$A$3:$A$832,'Space mix'!$G$3:$G$832)
A11: ='Space mix'!A11 | B11: ='Space mix'!B11 | F11: =XLOOKUP(A11,'Space mix'!$A$3:$A$832,'Space mix'!$G$3:$G$832)
A12: ='Space mix'!A12 | B12: ='Space mix'!B12 | F12: =XLOOKUP(A12,'Space mix'!$A$3:$A$832,'Space mix'!$G$3:$G$832)
A13: ='Space mix'!A13 | B13: ='Space mix'!B13 | F13: =XLOOKUP(A13,'Space mix'!$A$3:$A$832,'Space mix'!$G$3:$G$832)
A14: ='Space mix'!A14 | B14: ='Space mix'!B14 | F14: =XLOOKUP(A14,'Space mix'!$A$3:$A$832,'Space mix'!$G$3:$G$832)
... A832: ='Space mix'!A832 | B832: ='Space mix'!B832 | F832: =XLOOKUP(A832,'Space mix'!$A$3:$A$832,'Space mix'!$G$3:$G$832)
A833: ='Space mix'!A833 | B833: ='Space mix'!B833 | I833: =S833
A834: ='Space mix'!A834 | B834: ='Space mix'!B834
A835: ='Space mix'!A835 | B835: ='Space mix'!B835
A836: ='Space mix'!A836 | B836: ='Space mix'!B836
A837: ='Space mix'!A837 | B837: ='Space mix'!B837
A838: ='Space mix'!A838 | B838: ='Space mix'!B838
A839: ='Space mix'!A839 | B839: ='Space mix'!B839
A840: ='Space mix'!A840 | B840: ='Space mix'!B840
A841: ='Space mix'!A841 | B841: ='Space mix'!B841
A842: ='Space mix'!A842 | B842: ='Space mix'!B842
A843: ='Space mix'!A843 | B843: ='Space mix'!B843
A844: ='Space mix'!A844 | B844: ='Space mix'!B844
A845: ='Space mix'!A845 | B845: ='Space mix'!B845
... A1999: ='Space mix'!A1999 | B1999: ='Space mix'!B1999

Sheet Tenants Lien Holder Information
A1: ='Space mix'!A1 -> Space | B1: ='Space mix'!B1 | C1: ='Tenant Info'!C1 -> First Name | D1: ='Tenant Info'!D1 -> Last Name | E1: Lien Holder First Name | F1: Lien Holder Last Name | G1: Lien Holder Email | H1: Lien Holder Phone | I1: Lien Holder Address 1 | J1: Lien Holder Address 2 | K1: Lien Holder City | L1: Lien Holder State | M1: Lien Holder Zipcode
A2: ='Space mix'!A2 -> 101 or A-101 | B2: ='Space mix'!B2 -> Occupied or Vacant | C2: ='Tenant Info'!C2 -> Joe | D2: ='Tenant Info'!D2 -> Doe | E2: Anna | F2: Doe | G2: anna@email.com | H2: 2131110001 (no formatting) | I2: 4920 Campus Dr. | J2: Suite B | K2: Newport Beach | L2: CA | M2: 92612
A3: ='Space mix'!A3 | B3: ='Space mix'!B3 | C3: ='Tenant Info'!C3 | D3: ='Tenant Info'!D3
A4: ='Space mix'!A4 | B4: ='Space mix'!B4 | C4: ='Tenant Info'!C4 | D4: ='Tenant Info'!D4
A5: ='Space mix'!A5 | B5: ='Space mix'!B5 | C5: ='Tenant Info'!C5 | D5: ='Tenant Info'!D5
A6: ='Space mix'!A6 | B6: ='Space mix'!B6 | C6: ='Tenant Info'!C6 | D6: ='Tenant Info'!D6
A7: ='Space mix'!A7 | B7: ='Space mix'!B7 | C7: ='Tenant Info'!C7 | D7: ='Tenant Info'!D7
A8: ='Space mix'!A8 | B8: ='Space mix'!B8 | C8: ='Tenant Info'!C8 | D8: ='Tenant Info'!D8
A9: ='Space mix'!A9 | B9: ='Space mix'!B9 | C9: ='Tenant Info'!C9 | D9: ='Tenant Info'!D9
A10: ='Space mix'!A10 | B10: ='Space mix'!B10 | C10: ='Tenant Info'!C10 | D10: ='Tenant Info'!D10
A11: ='Space mix'!A11 | B11: ='Space mix'!B11 | C11: ='Tenant Info'!C11 | D11: ='Tenant Info'!D11
A12: ='Space mix'!A12 | B12: ='Space mix'!B12 | C12: ='Tenant Info'!C12 | D12: ='Tenant Info'!D12
A13: ='Space mix'!A13 | B13: ='Space mix'!B13 | C13: ='Tenant Info'!C13 | D13: ='Tenant Info'!D13
A14: ='Space mix'!A14 | B14: ='Space mix'!B14 | C14: ='Tenant Info'!C14 | D14: ='Tenant Info'!D14
... A1000: ='Space mix'!A1000 | B1000: ='Space mix'!B1000 | C1000: ='Tenant Info'!C1000 | D1000: ='Tenant Info'!D1000

Sheet Tenants Military Information
A1: ='Tenant Info'!A1 -> Space | B1: ='Space mix'!B1 | C1: ='Tenant Info'!H1 -> Active Military | D1: ='Tenant Info'!C1 -> First Name | E1: ='Tenant Info'!D1 -> Last Name | F1: Commanding Officer First Name | G1: Commanding Officer Last Name | H1: Commanding Officer Phone | I1: Commanding Officer Email | J1: Rank | K1: Military Serial Number | L1: Military Email | M1: Service Member DOB | N1: Expiration Term of Service | O1: Military Branch | P1: Military Unit Name | Q1: Military Unit Phone | R1: Military Unit Address 1 | S1: Military Unit Address 2 | T1: Military City | U1: Military Unit State | V1: Military Unit Zipcode
A2: ='Tenant Info'!A2 -> 101 or A-101 | B2: ='Space mix'!B2 -> Occupied or Vacant | C2: ='Tenant Info'!H2 -> [True/False] | D2: ='Tenant Info'!C2 -> Joe | E2: ='Tenant Info'!D2 -> Doe | F2: Joe | G2: Doe | H2: Doe | I2: joedoe@email.com | J2: Captain | K2: X111222 | L2: joe@usmilitary.com | M2: MM/DD/YYYY | N2: MM/DD/YYYY | O2: Navy | P2: Test | Q2: 2131110000 (no formatting) | R2: 4920 Campus Dr | S2: Suite B | T2: Irvine | U2: CA | V2: 92612
A3: ='Tenant Info'!A3 | B3: ='Space mix'!B3 | C3: ='Tenant Info'!H3 | D3: ='Tenant Info'!C3 | E3: ='Tenant Info'!D3
A4: ='Tenant Info'!A4 | B4: ='Space mix'!B4 | C4: ='Tenant Info'!H4 | D4: ='Tenant Info'!C4 | E4: ='Tenant Info'!D4
A5: ='Tenant Info'!A5 | B5: ='Space mix'!B5 | C5: ='Tenant Info'!H5 | D5: ='Tenant Info'!C5 | E5: ='Tenant Info'!D5
A6: ='Tenant Info'!A6 | B6: ='Space mix'!B6 | C6: ='Tenant Info'!H6 | D6: ='Tenant Info'!C6 | E6: ='Tenant Info'!D6
A7: ='Tenant Info'!A7 | B7: ='Space mix'!B7 | C7: ='Tenant Info'!H7 | D7: ='Tenant Info'!C7 | E7: ='Tenant Info'!D7
A8: ='Tenant Info'!A8 | B8: ='Space mix'!B8 | C8: ='Tenant Info'!H8 | D8: ='Tenant Info'!C8 | E8: ='Tenant Info'!D8
A9: ='Tenant Info'!A9 | B9: ='Space mix'!B9 | C9: ='Tenant Info'!H9 | D9: ='Tenant Info'!C9 | E9: ='Tenant Info'!D9
A10: ='Tenant Info'!A10 | B10: ='Space mix'!B10 | C10: ='Tenant Info'!H10 | D10: ='Tenant Info'!C10 | E10: ='Tenant Info'!D10
A11: ='Tenant Info'!A11 | B11: ='Space mix'!B11 | C11: ='Tenant Info'!H11 | D11: ='Tenant Info'!C11 | E11: ='Tenant Info'!D11
A12: ='Tenant Info'!A12 | B12: ='Space mix'!B12 | C12: ='Tenant Info'!H12 | D12: ='Tenant Info'!C12 | E12: ='Tenant Info'!D12
A13: ='Tenant Info'!A13 | B13: ='Space mix'!B13 | C13: ='Tenant Info'!H13 | D13: ='Tenant Info'!C13 | E13: ='Tenant Info'!D13
A14: ='Tenant Info'!A14 | B14: ='Space mix'!B14 | C14: ='Tenant Info'!H14 | D14: ='Tenant Info'!C14 | E14: ='Tenant Info'!D14
... A1999: ='Tenant Info'!A1999 | B1999: ='Space mix'!B1999 | C1999: ='Tenant Info'!H1999 | D1999: ='Tenant Info'!C1999 | E1999: ='Tenant Info'!D1999

Sheet PromotionsDiscounts
A1: ='Space mix'!A1 -> Space | B1: ='Tenant Info'!C1 -> First Name | C1: ='Tenant Info'!D1 -> Last Name | D1: Promotion | E1: Promotion Type | F1: Promotion Value | G1: Promotion Start | H1: Promotion Length | I1: Discount | J1: Discount Type | K1: Discount Value
A2: ='Space mix'!A2 -> 101 or A-101 | B2: ='Tenant Info'!C2 -> Joe | C2: ='Tenant Info'!D2 -> Doe | D2: [Promotion Name] | E2: [Promotion Fixed/Percentage/Dollar] | F2: 10 or 10.05 | G2: DD/MM/YYYY | H2: [Promotion Length Months] | I2: [Discount Name] | J2: [Discount Fixed/Percentage/Dollar] | K2: [Amount]
A3: ='Tenant Info'!A3 | B3: ='Tenant Info'!C3 | C3: ='Tenant Info'!D3
A4: ='Tenant Info'!A4 | B4: ='Tenant Info'!C4 | C4: ='Tenant Info'!D4
A5: ='Tenant Info'!A5 | B5: ='Tenant Info'!C5 | C5: ='Tenant Info'!D5
A6: ='Tenant Info'!A6 | B6: ='Tenant Info'!C6 | C6: ='Tenant Info'!D6
A7: ='Tenant Info'!A7 | B7: ='Tenant Info'!C7 | C7: ='Tenant Info'!D7
A8: ='Tenant Info'!A8 | B8: ='Tenant Info'!C8 | C8: ='Tenant Info'!D8
A9: ='Tenant Info'!A9 | B9: ='Tenant Info'!C9 | C9: ='Tenant Info'!D9
A10: ='Tenant Info'!A10 | B10: ='Tenant Info'!C10 | C10: ='Tenant Info'!D10
A11: ='Tenant Info'!A11 | B11: ='Tenant Info'!C11 | C11: ='Tenant Info'!D11
A12: ='Tenant Info'!A12 | B12: ='Tenant Info'!C12 | C12: ='Tenant Info'!D12
A13: ='Tenant Info'!A13 | B13: ='Tenant Info'!C13 | C13: ='Tenant Info'!D13
A14: ='Tenant Info'!A14 | B14: ='Tenant Info'!C14 | C14: ='Tenant Info'!D14
... A999: ='Tenant Info'!A999 | B999: ='Tenant Info'!C999 | C999: ='Tenant Info'!D999

Sheet Tenant Payment info
A1: ='Space mix'!A1 -> Space | B1: ='Space mix'!B1 | C1: ='Tenant Info'!C1 -> First Name | D1: ='Tenant Info'!D1 -> Last Name | E1: ='Tenant Info'!F1 -> Rent | F1: Last Rent Change Date | G1: ='Tenant Info'!G1 -> Move In Date | H1: Paid Date | I1: Bill Day | J1: Paid Through Date | K1: Validation FOM Only (Please see comment for instructions) | M1: Rent Balance | N1: Late Fees Balance | O1: Lien Fees Balance | P1: Fees Balance | Q1: Prepaid Rent | R1: Prepaid Additional Rent/Premium | S1: Tax Balance | T1: Prepaid Tax | U1: Security Deposit | V1: Security Deposit Balance | W1: Protection/Insurance Balance | X1: Protection/Insurance Provider | Y1: Protection/Insurance Coverage | Z1: Additional Rent/Premium | AA1: Merchandise Balance
A2: ='Space mix'!A2 -> 101 or A-101 | B2: ='Space mix'!B2 -> Occupied or Vacant | C2: ='Tenant Info'!C2 -> Joe | D2: ='Tenant Info'!D2 -> Doe | E2: ='Tenant Info'!F2 -> 100 or 100.05 | F2: MM/DD/YYYY | G2: ='Tenant Info'!G2 -> MM/DD/YYYY | H2: MM/DD/YYYY | I2: 1 | J2: MM/DD/YYYY | N2: 10 or 10.05 | O2: 10 or 10.06 | P2: 100 or 100.05 | Q2: 100 or 100.05 | R2: 9 or 9.05 | S2: 100 or 100.05 | T2: 100 or 100.05 | U2: 100 or 100.05 | V2: 100 or 100.05 | W2: 2 or 2.05 | X2: Storelocal Protection | Y2: 2500 | Z2: 9 or 9.05 | AA2: 9 or 9.05
A3: ='Tenant Info'!A3 | B3: ='Space mix'!B3 | C3: ='Tenant Info'!C3 | D3: ='Tenant Info'!D3 | E3: ='Tenant Info'!F3 | K3: =datedif(J3,$K$2,"m") | L3: =K3*E3
A4: ='Tenant Info'!A4 | B4: ='Space mix'!B4 | C4: ='Tenant Info'!C4 | D4: ='Tenant Info'!D4 | E4: ='Tenant Info'!F4
A5: ='Tenant Info'!A5 | B5: ='Space mix'!B5 | C5: ='Tenant Info'!C5 | D5: ='Tenant Info'!D5 | E5: ='Tenant Info'!F5
A6: ='Tenant Info'!A6 | B6: ='Space mix'!B6 | C6: ='Tenant Info'!C6 | D6: ='Tenant Info'!D6 | E6: ='Tenant Info'!F6
A7: ='Tenant Info'!A7 | B7: ='Space mix'!B7 | C7: ='Tenant Info'!C7 | D7: ='Tenant Info'!D7 | E7: ='Tenant Info'!F7
A8: ='Tenant Info'!A8 | B8: ='Space mix'!B8 | C8: ='Tenant Info'!C8 | D8: ='Tenant Info'!D8 | E8: ='Tenant Info'!F8
A9: ='Tenant Info'!A9 | B9: ='Space mix'!B9 | C9: ='Tenant Info'!C9 | D9: ='Tenant Info'!D9 | E9: ='Tenant Info'!F9
A10: ='Tenant Info'!A10 | B10: ='Space mix'!B10 | C10: ='Tenant Info'!C10 | D10: ='Tenant Info'!D10 | E10: ='Tenant Info'!F10
A11: ='Tenant Info'!A11 | B11: ='Space mix'!B11 | C11: ='Tenant Info'!C11 | D11: ='Tenant Info'!D11 | E11: ='Tenant Info'!F11
A12: ='Tenant Info'!A12 | B12: ='Space mix'!B12 | C12: ='Tenant Info'!C12 | D12: ='Tenant Info'!D12 | E12: ='Tenant Info'!F12
A13: ='Tenant Info'!A13 | B13: ='Space mix'!B13 | C13: ='Tenant Info'!C13 | D13: ='Tenant Info'!D13 | E13: ='Tenant Info'!F13
A14: ='Tenant Info'!A14 | B14: ='Space mix'!B14 | C14: ='Tenant Info'!C14 | D14: ='Tenant Info'!D14 | E14: ='Tenant Info'!F14
A15: ='Tenant Info'!A15 | B15: ='Space mix'!B15 | C15: ='Tenant Info'!C15 | D15: ='Tenant Info'!D15 | E15: ='Tenant Info'!F15
... A79: ='Tenant Info'!A79 | B79: ='Space mix'!B79 | C79: ='Tenant Info'!C79 | D79: ='Tenant Info'!D79 | E79: ='Tenant Info'!F79
A80: ='Tenant Info'!A80 | B80: ='Space mix'!B80 | C80: ='Tenant Info'!C80 | D80: ='Tenant Info'!D80 | E80: ='Tenant Info'!F80 | K80: =datedif(J80,$K$2,"m")
A81: ='Tenant Info'!A81 | B81: ='Space mix'!B81 | C81: ='Tenant Info'!C81 | D81: ='Tenant Info'!D81 | E81: ='Tenant Info'!F81
A82: ='Tenant Info'!A82 | B82: ='Space mix'!B82 | C82: ='Tenant Info'!C82 | D82: ='Tenant Info'!D82 | E82: ='Tenant Info'!F82
A83: ='Tenant Info'!A83 | B83: ='Space mix'!B83 | C83: ='Tenant Info'!C83 | D83: ='Tenant Info'!D83 | E83: ='Tenant Info'!F83
A84: ='Tenant Info'!A84 | B84: ='Space mix'!B84 | C84: ='Tenant Info'!C84 | D84: ='Tenant Info'!D84 | E84: ='Tenant Info'!F84
A85: ='Tenant Info'!A85 | B85: ='Space mix'!B85 | C85: ='Tenant Info'!C85 | D85: ='Tenant Info'!D85 | E85: ='Tenant Info'!F85
A86: ='Tenant Info'!A86 | B86: ='Space mix'!B86 | C86: ='Tenant Info'!C86 | D86: ='Tenant Info'!D86 | E86: ='Tenant Info'!F86
A87: ='Tenant Info'!A87 | B87: ='Space mix'!B87 | C87: ='Tenant Info'!C87 | D87: ='Tenant Info'!D87 | E87: ='Tenant Info'!F87
A88: ='Tenant Info'!A88 | B88: ='Space mix'!B88 | C88: ='Tenant Info'!C88 | D88: ='Tenant Info'!D88 | E88: ='Tenant Info'!F88
A89: ='Tenant Info'!A89 | B89: ='Space mix'!B89 | C89: ='Tenant Info'!C89 | D89: ='Tenant Info'!D89 | E89: ='Tenant Info'!F89
A90: ='Tenant Info'!A90 | B90: ='Space mix'!B90 | C90: ='Tenant Info'!C90 | D90: ='Tenant Info'!D90 | E90: ='Tenant Info'!F90
A91: ='Tenant Info'!A91 | B91: ='Space mix'!B91 | C91: ='Tenant Info'!C91 | D91: ='Tenant Info'!D91 | E91: ='Tenant Info'!F91
A92: ='Tenant Info'!A92 | B92: ='Space mix'!B92 | C92: ='Tenant Info'!C92 | D92: ='Tenant Info'!D92 | E92: ='Tenant Info'!F92
... A149: ='Tenant Info'!A149 | B149: ='Space mix'!B149 | C149: ='Tenant Info'!C149 | D149: ='Tenant Info'!D149 | E149: ='Tenant Info'!F149
A150: ='Tenant Info'!A150 | B150: ='Space mix'!B150 | C150: ='Tenant Info'!C150 | D150: ='Tenant Info'!D150 | E150: ='Tenant Info'!F150 | K150: =datedif(J150,$K$2,"m")
A151: ='Tenant Info'!A151 | B151: ='Space mix'!B151 | C151: ='Tenant Info'!C151 | D151: ='Tenant Info'!D151 | E151: ='Tenant Info'!F151
A152: ='Tenant Info'!A152 | B152: ='Space mix'!B152 | C152: ='Tenant Info'!C152 | D152: ='Tenant Info'!D152 | E152: ='Tenant Info'!F152
A153: ='Tenant Info'!A153 | B153: ='Space mix'!B153 | C153: ='Tenant Info'!C153 | D153: ='Tenant Info'!D153 | E153: ='Tenant Info'!F153
A154: ='Tenant Info'!A154 | B154: ='Space mix'!B154 | C154: ='Tenant Info'!C154 | D154: ='Tenant Info'!D154 | E154: ='Tenant Info'!F154
A155: ='Tenant Info'!A155 | B155: ='Space mix'!B155 | C155: ='Tenant Info'!C155 | D155: ='Tenant Info'!D155 | E155: ='Tenant Info'!F155
A156: ='Tenant Info'!A156 | B156: ='Space mix'!B156 | C156: ='Tenant Info'!C156 | D156: ='Tenant Info'!D156 | E156: ='Tenant Info'!F156
A157: ='Tenant Info'!A157 | B157: ='Space mix'!B157 | C157: ='Tenant Info'!C157 | D157: ='Tenant Info'!D157 | E157: ='Tenant Info'!F157
A158: ='Tenant Info'!A158 | B158: ='Space mix'!B158 | C158: ='Tenant Info'!C158 | D158: ='Tenant Info'!D158 | E158: ='Tenant Info'!F158
A159: ='Tenant Info'!A159 | B159: ='Space mix'!B159 | C159: ='Tenant Info'!C159 | D159: ='Tenant Info'!D159 | E159: ='Tenant Info'!F159
...

Sheet Final Sheet (View Only)
A1: Owner | B1: Name | C1: Building | D1: Occupied or Vacant | E1: ='Space mix'!A1 -> Space | F1: ='Space mix'!D1 -> Width | G1: ='Space mix'!E1 -> Length | H1: ='Space mix'!F1 -> Height | I1: ='Space mix'!G1 -> Rate | J1: Web Rate (not there on app right now) | K1: ='Space mix'!L1 -> Space Size | L1: ='Space mix'!H1 -> Space Category | M1: ='Space mix'!C1 -> Space Type | N1: ='Space mix'!J1 -> Door Width | O1: ='Space mix'!K1 -> Door Height | P1: Amenities | Q1: ='Space mix'!M1 -> Sq. Ft. | R1: ='Space mix'!I1 -> Floor | S1: ='Tenant Info'!C1 -> First Name | T1: ='Tenant Info'!D1 -> Last Name | U1: ='Tenant Info'!E1 -> Middle Name | V1: ='Tenant Info'!I1 -> Account Code | W1: ='Tenant Info'!J1 -> Address | X1: ='Tenant Info'!K1 -> City | Y1: ='Tenant Info'!L1 -> State | Z1: ='Tenant Info'!M1 -> ZIP | AA1: ='Tenant Info'!N1 -> Country | AB1: ='Tenant Info'!O1 -> Email | AC1: ='Tenant Info'!P1 -> Cell Phone | ... AF1: ='Tenant Info'!S1 -> Access Code | AG1: DOB | AH1: Gender | AI1: ='Tenant Info'!H1 -> Active Military | AJ1: ='Tenant Info'!T1 -> DL Id | AK1: ='Tenant Info'!U1 -> DL State | AL1: ='Tenant Info'!V1 -> DL City | AM1: ='Tenant Info'!W1 -> DL Exp Date | AN1: ='Tenant Info'!F1 -> Rent | AO1: ='Tenant Payment info'!F1 -> Last Rent Change Date | AP1: ='Tenant Info'!G1 -> Move In Date | AQ1: Move Out Date | AR1: ='Tenant Payment info'!H1 -> Paid Date | AS1: ='Tenant Payment info'!I1 -> Bill Day | AT1: ='Tenant Payment info'!J1 -> Paid Through Date | AU1: ='Tenant Info'!X1 -> Alt First Name | AV1: ='Tenant Info'!Y1 -> Alt Last Name | AW1: ='Tenant Info'!Z1 -> Alt Middle Name | AX1: ='Tenant Info'!AA1 -> Alt Address | AY1: ='Tenant Info'!AB1 -> Alt City | AZ1: ='Tenant Info'!AC1 -> Alt State | BA1: ='Tenant Info'!AD1 -> Alt ZIP | BB1: ='Tenant Info'!AE1 -> Alt Email | ... BE1: ='Tenant Info'!AH1 -> Alt Cell Phone | BF1: ='Tenant Payment info'!U1 -> Security Deposit | BG1: ='Tenant Payment info'!V1 -> Security Deposit Balance | BH1: ='Tenant Payment info'!M1 -> Rent Balance | BI1: ='Tenant Payment info'!P1 -> Fees Balance | BJ1: ='Tenant Payment info'!W1 -> Protection/Insurance Balance | BK1: ='Tenant Payment info'!AA1 -> Merchandise Balance | BL1: ='Tenant Payment info'!N1 -> Late Fees Balance | BM1: ='Tenant Payment info'!O1 -> Lien Fees Balance | BN1: ='Tenant Payment info'!S1 -> Tax Balance | BO1: ='Tenant Payment info'!Q1 -> Prepaid Rent | BP1: ='Tenant Payment info'!R1 -> Prepaid Additional Rent/Premium | BQ1: ='Tenant Payment info'!T1 -> Prepaid Tax | BR1: ='Tenant Payment info'!X1 -> Protection/Insurance Provider | BS1: ='Tenant Payment info'!Y1 -> Protection/Insurance Coverage | BT1: ='Tenant Payment info'!Z1 -> Additional Rent/Premium | BU1: Delinquency Status | BV1: Lien Status | BW1: Lien Posted Date | BX1: =PromotionsDiscounts!D1 -> Promotion | BY1: =PromotionsDiscounts!E1 -> Promotion Type | BZ1: =PromotionsDiscounts!F1 -> Promotion Value | CA1: =PromotionsDiscounts!G1 -> Promotion Start | CB1: =PromotionsDiscounts!H1 -> Promotion Length | CC1: =PromotionsDiscounts!I1 -> Discount | CD1: =PromotionsDiscounts!J1 -> Discount Type | CE1: =PromotionsDiscounts!K1 -> Discount Value | CF1: ='Tenants Military Information'!F1 -> Commanding Officer First Name | CG1: ='Tenants Military Information'!G1 -> Commanding Officer Last Name | CH1: ='Tenants Military Information'!H1 -> Commanding Officer Phone | CI1: ='Tenants Military Information'!I1 -> Commanding Officer Email | CJ1: ='Tenants Military Information'!J1 -> Rank | CK1: ='Tenants Military Information'!K1 -> Military Serial Number | CL1: ='Tenants Military Information'!L1 -> Military Email | CM1: ='Tenants Military Information'!M1 -> Service Member DOB | ... CV1: ='Tenants Military Information'!V1 -> Military Unit Zipcode | CW1: ='Tenants Lien Holder Information'!E1 -> Lien Holder First Name | CX1: ='Tenants Lien Holder Information'!F1 -> Lien Holder Last Name | CY1: ='Tenants Lien Holder Information'!G1 -> Lien Holder Email | CZ1: ='Tenants Lien Holder Information'!H1 -> Lien Holder Phone | DA1: ='Tenants Lien Holder Information'!I1 -> Lien Holder Address 1 | DB1: ='Tenants Lien Holder Information'!J1 -> Lien Holder Address 2 | DC1: ='Tenants Lien Holder Information'!K1 -> Lien Holder City | DD1: ='Tenants Lien Holder Information'!L1 -> Lien Holder State | DE1: ='Tenants Lien Holder Information'!M1 -> Lien Holder Zipcode
D2: ='Space mix'!B2 | E2: ='Space mix'!A2 | F2: ='Space mix'!D2 | G2: ='Space mix'!E2 | H2: ='Space mix'!F2 | I2: ='Space mix'!G2 | K2: ='Space mix'!L2 | L2: ='Space mix'!H2 | M2: ='Space mix'!C2 | N2: ='Space mix'!J2 | O2: ='Space mix'!K2 | Q2: ='Space mix'!M2 | R2: ='Space mix'!I2 | S2: ='Tenant Info'!C2 | T2: ='Tenant Info'!D2 | U2: ='Tenant Info'!E2 | V2: ='Tenant Info'!I2 | W2: ='Tenant Info'!J2 | X2: ='Tenant Info'!K2 | Y2: ='Tenant Info'!L2 | Z2: ='Tenant Info'!M2 | AA2: ='Tenant Info'!N2 | AB2: ='Tenant Info'!O2 | AC2: ='Tenant Info'!P2 | ... AF2: ='Tenant Info'!S2 | AI2: ='Tenant Info'!H2 | AJ2: ='Tenant Info'!T2 | AK2: ='Tenant Info'!U2 | AL2: ='Tenant Info'!V2 | AM2: ='Tenant Info'!W2 | AN2: ='Tenant Info'!F2 | AO2: ='Tenant Payment info'!F2 | AP2: ='Tenant Info'!G2 | AR2: ='Tenant Payment info'!H2 | AS2: ='Tenant Payment info'!I2 | AT2: ='Tenant Payment info'!J2 | AU2: ='Tenant Info'!X2 | AV2: ='Tenant Info'!Y2 | AW2: ='Tenant Info'!Z2 | AX2: ='Tenant Info'!AA2 | AY2: ='Tenant Info'!AB2 | AZ2: ='Tenant Info'!AC2 | BA2: ='Tenant Info'!AD2 | BB2: ='Tenant Info'!AE2 | ... BE2: ='Tenant Info'!AH2 | BF2: ='Tenant Payment info'!U2 | BG2: ='Tenant Payment info'!V2 | BH2: ='Tenant Payment info'!M2 | BI2: ='Tenant Payment info'!P2 | BJ2: ='Tenant Payment info'!W2 | BK2: ='Tenant Payment info'!AA2 | BL2: ='Tenant Payment info'!N2 | BM2: ='Tenant Payment info'!O2 | BN2: ='Tenant Payment info'!S2 | BO2: ='Tenant Payment info'!Q2 | BP2: ='Tenant Payment info'!R2 | BQ2: ='Tenant Payment info'!T2 | BR2: ='Tenant Payment info'!X2 | BS2: ='Tenant Payment info'!Y2 | BT2: ='Tenant Payment info'!Z2 | BX2: =PromotionsDiscounts!D2 | BY2: =PromotionsDiscounts!E2 | BZ2: =PromotionsDiscounts!F2 | CA2: =PromotionsDiscounts!G2 | CB2: =PromotionsDiscounts!H2 | CC2: =PromotionsDiscounts!I2 | CD2: =PromotionsDiscounts!J2 | CE2: =PromotionsDiscounts!K2 | CF2: ='Tenants Military Information'!F2 | CG2: ='Tenants Military Information'!G2 | CH2: ='Tenants Military Information'!H2 | CI2: ='Tenants Military Information'!I2 | CJ2: ='Tenants Military Information'!J2 | CK2: ='Tenants Military Information'!K2 | CL2: ='Tenants Military Information'!L2 | CM2: ='Tenants Military Information'!M2 | ... CV2: ='Tenants Military Information'!V2 | CW2: ='Tenants Lien Holder Information'!E2 | CX2: ='Tenants Lien Holder Information'!F2 | CY2: ='Tenants Lien Holder Information'!G2 | CZ2: ='Tenants Lien Holder Information'!H2 | DA2: ='Tenants Lien Holder Information'!I2 | DB2: ='Tenants Lien Holder Information'!J2 | DC2: ='Tenants Lien Holder Information'!K2 | DD2: ='Tenants Lien Holder Information'!L2 | DE2: ='Tenants Lien Holder Information'!M2
D3: ='Space mix'!B3 | E3: ='Space mix'!A3 | F3: ='Space mix'!D3 | G3: ='Space mix'!E3 | H3: ='Space mix'!F3 | I3: ='Space mix'!G3 | J3: =I3 | K3: ='Space mix'!L3 | L3: ='Space mix'!H3 | M3: ='Space mix'!C3 | N3: ='Space mix'!J3 | O3: ='Space mix'!K3 | Q3: ='Space mix'!M3 | R3: ='Space mix'!I3 | S3: ='Tenant Info'!C3 | T3: ='Tenant Info'!D3 | U3: ='Tenant Info'!E3 | V3: ='Tenant Info'!I3 | W3: ='Tenant Info'!J3 | X3: ='Tenant Info'!K3 | Y3: ='Tenant Info'!L3 | Z3: ='Tenant Info'!M3 | AA3: ='Tenant Info'!N3 | AB3: ='Tenant Info'!O3 | AC3: ='Tenant Info'!P3 | ... AF3: ='Tenant Info'!S3 | AI3: ='Tenant Info'!H3 | AJ3: ='Tenant Info'!T3 | AK3: ='Tenant Info'!U3 | AL3: ='Tenant Info'!V3 | AM3: ='Tenant Info'!W3 | AN3: ='Tenant Info'!F3 | AP3: ='Tenant Info'!G3 | AR3: ='Tenant Payment info'!H3 | AS3: ='Tenant Payment info'!I3 | AT3: ='Tenant Payment info'!J3 | AU3: ='Tenant Info'!X3 | AV3: ='Tenant Info'!Y3 | AW3: ='Tenant Info'!Z3 | AX3: ='Tenant Info'!AA3 | AY3: ='Tenant Info'!AB3 | AZ3: ='Tenant Info'!AC3 | BA3: ='Tenant Info'!AD3 | BB3: ='Tenant Info'!AE3 | ... BE3: ='Tenant Info'!AH3 | BF3: ='Tenant Payment info'!U3 | BG3: ='Tenant Payment info'!V3 | BH3: ='Tenant Payment info'!M3 | BI3: ='Tenant Payment info'!P3 | BJ3: ='Tenant Payment info'!W3 | BK3: ='Tenant Payment info'!AA3 | BL3: ='Tenant Payment info'!N3 | BM3: ='Tenant Payment info'!O3 | BN3: ='Tenant Payment info'!S3 | BO3: ='Tenant Payment info'!Q3 | BP3: ='Tenant Payment info'!R3 | BQ3: ='Tenant Payment info'!T3 | BR3: ='Tenant Payment info'!X3 | BS3: ='Tenant Payment info'!Y3 | BT3: ='Tenant Payment info'!Z3 | BX3: =PromotionsDiscounts!D3 | BY3: =PromotionsDiscounts!E3 | BZ3: =PromotionsDiscounts!F3 | CA3: =PromotionsDiscounts!G3 | CB3: =PromotionsDiscounts!H3 | CC3: =PromotionsDiscounts!I3 | CD3: =PromotionsDiscounts!J3 | CE3: =PromotionsDiscounts!K3 | CF3: ='Tenants Military Information'!F3 | CG3: ='Tenants Military Information'!G3 | CH3: ='Tenants Military Information'!H3 | CI3: ='Tenants Military Information'!I3 | CJ3: ='Tenants Military Information'!J3 | CK3: ='Tenants Military Information'!K3 | CL3: ='Tenants Military Information'!L3 | CM3: ='Tenants Military Information'!M3 | ... CV3: ='Tenants Military Information'!V3 | CW3: ='Tenants Lien Holder Information'!E3 | CX3: ='Tenants Lien Holder Information'!F3 | CY3: ='Tenants Lien Holder Information'!G3 | CZ3: ='Tenants Lien Holder Information'!H3 | DA3: ='Tenants Lien Holder Information'!I3 | DB3: ='Tenants Lien Holder Information'!J3 | DC3: ='Tenants Lien Holder Information'!K3 | DD3: ='Tenants Lien Holder Information'!L3 | DE3: ='Tenants Lien Holder Information'!M3
D4: ='Space mix'!B4 | E4: ='Space mix'!A4 | F4: ='Space mix'!D4 | G4: ='Space mix'!E4 | H4: ='Space mix'!F4 | I4: ='Space mix'!G4 | K4: ='Space mix'!L4 | L4: ='Space mix'!H4 | M4: ='Space mix'!C4 | N4: ='Space mix'!J4 | O4: ='Space mix'!K4 | Q4: ='Space mix'!M4 | R4: ='Space mix'!I4 | S4: ='Tenant Info'!C4 | T4: ='Tenant Info'!D4 | U4: ='Tenant Info'!E4 | V4: ='Tenant Info'!I4 | W4: ='Tenant Info'!J4 | X4: ='Tenant Info'!K4 | Y4: ='Tenant Info'!L4 | Z4: ='Tenant Info'!M4 | AA4: ='Tenant Info'!N4 | AB4: ='Tenant Info'!O4 | AC4: ='Tenant Info'!P4 | ... AF4: ='Tenant Info'!S4 | AI4: ='Tenant Info'!H4 | AJ4: ='Tenant Info'!T4 | AK4: ='Tenant Info'!U4 | AL4: ='Tenant Info'!V4 | AM4: ='Tenant Info'!W4 | AN4: ='Tenant Info'!F4 | AP4: ='Tenant Info'!G4 | AR4: ='Tenant Payment info'!H4 | AS4: ='Tenant Payment info'!I4 | AT4: ='Tenant Payment info'!J4 | AU4: ='Tenant Info'!X4 | AV4: ='Tenant Info'!Y4 | AW4: ='Tenant Info'!Z4 | AX4: ='Tenant Info'!AA4 | AY4: ='Tenant Info'!AB4 | AZ4: ='Tenant Info'!AC4 | BA4: ='Tenant Info'!AD4 | BB4: ='Tenant Info'!AE4 | ... BE4: ='Tenant Info'!AH4 | BF4: ='Tenant Payment info'!U4 | BG4: ='Tenant Payment info'!V4 | BH4: ='Tenant Payment info'!M4 | BI4: ='Tenant Payment info'!P4 | BJ4: ='Tenant Payment info'!W4 | BK4: ='Tenant Payment info'!AA4 | BL4: ='Tenant Payment info'!N4 | BM4: ='Tenant Payment info'!O4 | BN4: ='Tenant Payment info'!S4 | BO4: ='Tenant Payment info'!Q4 | BP4: ='Tenant Payment info'!R4 | BQ4: ='Tenant Payment info'!T4 | BR4: ='Tenant Payment info'!X4 | BS4: ='Tenant Payment info'!Y4 | BT4: ='Tenant Payment info'!Z4 | BX4: =PromotionsDiscounts!D4 | BY4: =PromotionsDiscounts!E4 | BZ4: =PromotionsDiscounts!F4 | CA4: =PromotionsDiscounts!G4 | CB4: =PromotionsDiscounts!H4 | CC4: =PromotionsDiscounts!I4 | CD4: =PromotionsDiscounts!J4 | CE4: =PromotionsDiscounts!K4 | CF4: ='Tenants Military Information'!F4 | CG4: ='Tenants Military Information'!G4 | CH4: ='Tenants Military Information'!H4 | CI4: ='Tenants Military Information'!I4 | CJ4: ='Tenants Military Information'!J4 | CK4: ='Tenants Military Information'!K4 | CL4: ='Tenants Military Information'!L4 | CM4: ='Tenants Military Information'!M4 | ... CV4: ='Tenants Military Information'!V4 | CW4: ='Tenants Lien Holder Information'!E4 | CX4: ='Tenants Lien Holder Information'!F4 | CY4: ='Tenants Lien Holder Information'!G4 | CZ4: ='Tenants Lien Holder Information'!H4 | DA4: ='Tenants Lien Holder Information'!I4 | DB4: ='Tenants Lien Holder Information'!J4 | DC4: ='Tenants Lien Holder Information'!K4 | DD4: ='Tenants Lien Holder Information'!L4 | DE4: ='Tenants Lien Holder Information'!M4
D5: ='Space mix'!B5 | E5: ='Space mix'!A5 | F5: ='Space mix'!D5 | G5: ='Space mix'!E5 | H5: ='Space mix'!F5 | I5: ='Space mix'!G5 | K5: ='Space mix'!L5 | L5: ='Space mix'!H5 | M5: ='Space mix'!C5 | N5: ='Space mix'!J5 | O5: ='Space mix'!K5 | Q5: ='Space mix'!M5 | R5: ='Space mix'!I5 | S5: ='Tenant Info'!C5 | T5: ='Tenant Info'!D5 | U5: ='Tenant Info'!E5 | V5: ='Tenant Info'!I5 | W5: ='Tenant Info'!J5 | X5: ='Tenant Info'!K5 | Y5: ='Tenant Info'!L5 | Z5: ='Tenant Info'!M5 | AA5: ='Tenant Info'!N5 | AB5: ='Tenant Info'!O5 | AC5: ='Tenant Info'!P5 | ... AF5: ='Tenant Info'!S5 | AI5: ='Tenant Info'!H5 | AJ5: ='Tenant Info'!T5 | AK5: ='Tenant Info'!U5 | AL5: ='Tenant Info'!V5 | AM5: ='Tenant Info'!W5 | AN5: ='Tenant Info'!F5 | AP5: ='Tenant Info'!G5 | AR5: ='Tenant Payment info'!H5 | AS5: ='Tenant Payment info'!I5 | AT5: ='Tenant Payment info'!J5 | AU5: ='Tenant Info'!X5 | AV5: ='Tenant Info'!Y5 | AW5: ='Tenant Info'!Z5 | AX5: ='Tenant Info'!AA5 | AY5: ='Tenant Info'!AB5 | AZ5: ='Tenant Info'!AC5 | BA5: ='Tenant Info'!AD5 | BB5: ='Tenant Info'!AE5 | ... BE5: ='Tenant Info'!AH5 | BF5: ='Tenant Payment info'!U5 | BG5: ='Tenant Payment info'!V5 | BH5: ='Tenant Payment info'!M5 | BI5: ='Tenant Payment info'!P5 | BJ5: ='Tenant Payment info'!W5 | BK5: ='Tenant Payment info'!AA5 | BL5: ='Tenant Payment info'!N5 | BM5: ='Tenant Payment info'!O5 | BN5: ='Tenant Payment info'!S5 | BO5: ='Tenant Payment info'!Q5 | BP5: ='Tenant Payment info'!R5 | BQ5: ='Tenant Payment info'!T5 | BR5: ='Tenant Payment info'!X5 | BS5: ='Tenant Payment info'!Y5 | BT5: ='Tenant Payment info'!Z5 | BX5: =PromotionsDiscounts!D5 | BY5: =PromotionsDiscounts!E5 | BZ5: =PromotionsDiscounts!F5 | CA5: =PromotionsDiscounts!G5 | CB5: =PromotionsDiscounts!H5 | CC5: =PromotionsDiscounts!I5 | CD5: =PromotionsDiscounts!J5 | CE5: =PromotionsDiscounts!K5 | CF5: ='Tenants Military Information'!F5 | CG5: ='Tenants Military Information'!G5 | CH5: ='Tenants Military Information'!H5 | CI5: ='Tenants Military Information'!I5 | CJ5: ='Tenants Military Information'!J5 | CK5: ='Tenants Military Information'!K5 | CL5: ='Tenants Military Information'!L5 | CM5: ='Tenants Military Information'!M5 | ... CV5: ='Tenants Military Information'!V5 | CW5: ='Tenants Lien Holder Information'!E5 | CX5: ='Tenants Lien Holder Information'!F5 | CY5: ='Tenants Lien Holder Information'!G5 | CZ5: ='Tenants Lien Holder Information'!H5 | DA5: ='Tenants Lien Holder Information'!I5 | DB5: ='Tenants Lien Holder Information'!J5 | DC5: ='Tenants Lien Holder Information'!K5 | DD5: ='Tenants Lien Holder Information'!L5 | DE5: ='Tenants Lien Holder Information'!M5
D6: ='Space mix'!B6 | E6: ='Space mix'!A6 | F6: ='Space mix'!D6 | G6: ='Space mix'!E6 | H6: ='Space mix'!F6 | I6: ='Space mix'!G6 | K6: ='Space mix'!L6 | L6: ='Space mix'!H6 | M6: ='Space mix'!C6 | N6: ='Space mix'!J6 | O6: ='Space mix'!K6 | Q6: ='Space mix'!M6 | R6: ='Space mix'!I6 | S6: ='Tenant Info'!C6 | T6: ='Tenant Info'!D6 | U6: ='Tenant Info'!E6 | V6: ='Tenant Info'!I6 | W6: ='Tenant Info'!J6 | X6: ='Tenant Info'!K6 | Y6: ='Tenant Info'!L6 | Z6: ='Tenant Info'!M6 | AA6: ='Tenant Info'!N6 | AB6: ='Tenant Info'!O6 | AC6: ='Tenant Info'!P6 | ... AF6: ='Tenant Info'!S6 | AI6: ='Tenant Info'!H6 | AJ6: ='Tenant Info'!T6 | AK6: ='Tenant Info'!U6 | AL6: ='Tenant Info'!V6 | AM6: ='Tenant Info'!W6 | AN6: ='Tenant Info'!F6 | AP6: ='Tenant Info'!G6 | AR6: ='Tenant Payment info'!H6 | AS6: ='Tenant Payment info'!I6 | AT6: ='Tenant Payment info'!J6 | AU6: ='Tenant Info'!X6 | AV6: ='Tenant Info'!Y6 | AW6: ='Tenant Info'!Z6 | AX6: ='Tenant Info'!AA6 | AY6: ='Tenant Info'!AB6 | AZ6: ='Tenant Info'!AC6 | BA6: ='Tenant Info'!AD6 | BB6: ='Tenant Info'!AE6 | ... BE6: ='Tenant Info'!AH6 | BF6: ='Tenant Payment info'!U6 | BG6: ='Tenant Payment info'!V6 | BH6: ='Tenant Payment info'!M6 | BI6: ='Tenant Payment info'!P6 | BJ6: ='Tenant Payment info'!W6 | BK6: ='Tenant Payment info'!AA6 | BL6: ='Tenant Payment info'!N6 | BM6: ='Tenant Payment info'!O6 | BN6: ='Tenant Payment info'!S6 | BO6: ='Tenant Payment info'!Q6 | BP6: ='Tenant Payment info'!R6 | BQ6: ='Tenant Payment info'!T6 | BR6: ='Tenant Payment info'!X6 | BS6: ='Tenant Payment info'!Y6 | BT6: ='Tenant Payment info'!Z6 | BX6: =PromotionsDiscounts!D6 | BY6: =PromotionsDiscounts!E6 | BZ6: =PromotionsDiscounts!F6 | CA6: =PromotionsDiscounts!G6 | CB6: =PromotionsDiscounts!H6 | CC6: =PromotionsDiscounts!I6 | CD6: =PromotionsDiscounts!J6 | CE6: =PromotionsDiscounts!K6 | CF6: ='Tenants Military Information'!F6 | CG6: ='Tenants Military Information'!G6 | CH6: ='Tenants Military Information'!H6 | CI6: ='Tenants Military Information'!I6 | CJ6: ='Tenants Military Information'!J6 | CK6: ='Tenants Military Information'!K6 | CL6: ='Tenants Military Information'!L6 | CM6: ='Tenants Military Information'!M6 | ... CV6: ='Tenants Military Information'!V6 | CW6: ='Tenants Lien Holder Information'!E6 | CX6: ='Tenants Lien Holder Information'!F6 | CY6: ='Tenants Lien Holder Information'!G6 | CZ6: ='Tenants Lien Holder Information'!H6 | DA6: ='Tenants Lien Holder Information'!I6 | DB6: ='Tenants Lien Holder Information'!J6 | DC6: ='Tenants Lien Holder Information'!K6 | DD6: ='Tenants Lien Holder Information'!L6 | DE6: ='Tenants Lien Holder Information'!M6
D7: ='Space mix'!B7 | E7: ='Space mix'!A7 | F7: ='Space mix'!D7 | G7: ='Space mix'!E7 | H7: ='Space mix'!F7 | I7: ='Space mix'!G7 | K7: ='Space mix'!L7 | L7: ='Space mix'!H7 | M7: ='Space mix'!C7 | N7: ='Space mix'!J7 | O7: ='Space mix'!K7 | Q7: ='Space mix'!M7 | R7: ='Space mix'!I7 | S7: ='Tenant Info'!C7 | T7: ='Tenant Info'!D7 | U7: ='Tenant Info'!E7 | V7: ='Tenant Info'!I7 | W7: ='Tenant Info'!J7 | X7: ='Tenant Info'!K7 | Y7: ='Tenant Info'!L7 | Z7: ='Tenant Info'!M7 | AA7: ='Tenant Info'!N7 | AB7: ='Tenant Info'!O7 | AC7: ='Tenant Info'!P7 | ... AF7: ='Tenant Info'!S7 | AI7: ='Tenant Info'!H7 | AJ7: ='Tenant Info'!T7 | AK7: ='Tenant Info'!U7 | AL7: ='Tenant Info'!V7 | AM7: ='Tenant Info'!W7 | AN7: ='Tenant Info'!F7 | AP7: ='Tenant Info'!G7 | AR7: ='Tenant Payment info'!H7 | AS7: ='Tenant Payment info'!I7 | AT7: ='Tenant Payment info'!J7 | AU7: ='Tenant Info'!X7 | AV7: ='Tenant Info'!Y7 | AW7: ='Tenant Info'!Z7 | AX7: ='Tenant Info'!AA7 | AY7: ='Tenant Info'!AB7 | AZ7: ='Tenant Info'!AC7 | BA7: ='Tenant Info'!AD7 | BB7: ='Tenant Info'!AE7 | ... BE7: ='Tenant Info'!AH7 | BF7: ='Tenant Payment info'!U7 | BG7: ='Tenant Payment info'!V7 | BH7: ='Tenant Payment info'!M7 | BI7: ='Tenant Payment info'!P7 | BJ7: ='Tenant Payment info'!W7 | BK7: ='Tenant Payment info'!AA7 | BL7: ='Tenant Payment info'!N7 | BM7: ='Tenant Payment info'!O7 | BN7: ='Tenant Payment info'!S7 | BO7: ='Tenant Payment info'!Q7 | BP7: ='Tenant Payment info'!R7 | BQ7: ='Tenant Payment info'!T7 | BR7: ='Tenant Payment info'!X7 | BS7: ='Tenant Payment info'!Y7 | BT7: ='Tenant Payment info'!Z7 | BX7: =PromotionsDiscounts!D7 | BY7: =PromotionsDiscounts!E7 | BZ7: =PromotionsDiscounts!F7 | CA7: =PromotionsDiscounts!G7 | CB7: =PromotionsDiscounts!H7 | CC7: =PromotionsDiscounts!I7 | CD7: =PromotionsDiscounts!J7 | CE7: =PromotionsDiscounts!K7 | CF7: ='Tenants Military Information'!F7 | CG7: ='Tenants Military Information'!G7 | CH7: ='Tenants Military Information'!H7 | CI7: ='Tenants Military Information'!I7 | CJ7: ='Tenants Military Information'!J7 | CK7: ='Tenants Military Information'!K7 | CL7: ='Tenants Military Information'!L7 | CM7: ='Tenants Military Information'!M7 | ... CV7: ='Tenants Military Information'!V7 | CW7: ='Tenants Lien Holder Information'!E7 | CX7: ='Tenants Lien Holder Information'!F7 | CY7: ='Tenants Lien Holder Information'!G7 | CZ7: ='Tenants Lien Holder Information'!H7 | DA7: ='Tenants Lien Holder Information'!I7 | DB7: ='Tenants Lien Holder Information'!J7 | DC7: ='Tenants Lien Holder Information'!K7 | DD7: ='Tenants Lien Holder Information'!L7 | DE7: ='Tenants Lien Holder Information'!M7
D8: ='Space mix'!B8 | E8: ='Space mix'!A8 | F8: ='Space mix'!D8 | G8: ='Space mix'!E8 | H8: ='Space mix'!F8 | I8: ='Space mix'!G8 | K8: ='Space mix'!L8 | L8: ='Space mix'!H8 | M8: ='Space mix'!C8 | N8: ='Space mix'!J8 | O8: ='Space mix'!K8 | Q8: ='Space mix'!M8 | R8: ='Space mix'!I8 | S8: ='Tenant Info'!C8 | T8: ='Tenant Info'!D8 | U8: ='Tenant Info'!E8 | V8: ='Tenant Info'!I8 | W8: ='Tenant Info'!J8 | X8: ='Tenant Info'!K8 | Y8: ='Tenant Info'!L8 | Z8: ='Tenant Info'!M8 | AA8: ='Tenant Info'!N8 | AB8: ='Tenant Info'!O8 | AC8: ='Tenant Info'!P8 | ... AF8: ='Tenant Info'!S8 | AI8: ='Tenant Info'!H8 | AJ8: ='Tenant Info'!T8 | AK8: ='Tenant Info'!U8 | AL8: ='Tenant Info'!V8 | AM8: ='Tenant Info'!W8 | AN8: ='Tenant Info'!F8 | AP8: ='Tenant Info'!G8 | AR8: ='Tenant Payment info'!H8 | AS8: ='Tenant Payment info'!I8 | AT8: ='Tenant Payment info'!J8 | AU8: ='Tenant Info'!X8 | AV8: ='Tenant Info'!Y8 | AW8: ='Tenant Info'!Z8 | AX8: ='Tenant Info'!AA8 | AY8: ='Tenant Info'!AB8 | AZ8: ='Tenant Info'!AC8 | BA8: ='Tenant Info'!AD8 | BB8: ='Tenant Info'!AE8 | ... BE8: ='Tenant Info'!AH8 | BF8: ='Tenant Payment info'!U8 | BG8: ='Tenant Payment info'!V8 | BH8: ='Tenant Payment info'!M8 | BI8: ='Tenant Payment info'!P8 | BJ8: ='Tenant Payment info'!W8 | BK8: ='Tenant Payment info'!AA8 | BL8: ='Tenant Payment info'!N8 | BM8: ='Tenant Payment info'!O8 | BN8: ='Tenant Payment info'!S8 | BO8: ='Tenant Payment info'!Q8 | BP8: ='Tenant Payment info'!R8 | BQ8: ='Tenant Payment info'!T8 | BR8: ='Tenant Payment info'!X8 | BS8: ='Tenant Payment info'!Y8 | BT8: ='Tenant Payment info'!Z8 | BX8: =PromotionsDiscounts!D8 | BY8: =PromotionsDiscounts!E8 | BZ8: =PromotionsDiscounts!F8 | CA8: =PromotionsDiscounts!G8 | CB8: =PromotionsDiscounts!H8 | CC8: =PromotionsDiscounts!I8 | CD8: =PromotionsDiscounts!J8 | CE8: =PromotionsDiscounts!K8 | CF8: ='Tenants Military Information'!F8 | CG8: ='Tenants Military Information'!G8 | CH8: ='Tenants Military Information'!H8 | CI8: ='Tenants Military Information'!I8 | CJ8: ='Tenants Military Information'!J8 | CK8: ='Tenants Military Information'!K8 | CL8: ='Tenants Military Information'!L8 | CM8: ='Tenants Military Information'!M8 | ... CV8: ='Tenants Military Information'!V8 | CW8: ='Tenants Lien Holder Information'!E8 | CX8: ='Tenants Lien Holder Information'!F8 | CY8: ='Tenants Lien Holder Information'!G8 | CZ8: ='Tenants Lien Holder Information'!H8 | DA8: ='Tenants Lien Holder Information'!I8 | DB8: ='Tenants Lien Holder Information'!J8 | DC8: ='Tenants Lien Holder Information'!K8 | DD8: ='Tenants Lien Holder Information'!L8 | DE8: ='Tenants Lien Holder Information'!M8
D9: ='Space mix'!B9 | E9: ='Space mix'!A9 | F9: ='Space mix'!D9 | G9: ='Space mix'!E9 | H9: ='Space mix'!F9 | I9: ='Space mix'!G9 | K9: ='Space mix'!L9 | L9: ='Space mix'!H9 | M9: ='Space mix'!C9 | N9: ='Space mix'!J9 | O9: ='Space mix'!K9 | Q9: ='Space mix'!M9 | R9: ='Space mix'!I9 | S9: ='Tenant Info'!C9 | T9: ='Tenant Info'!D9 | U9: ='Tenant Info'!E9 | V9: ='Tenant Info'!I9 | W9: ='Tenant Info'!J9 | X9: ='Tenant Info'!K9 | Y9: ='Tenant Info'!L9 | Z9: ='Tenant Info'!M9 | AA9: ='Tenant Info'!N9 | AB9: ='Tenant Info'!O9 | AC9: ='Tenant Info'!P9 | ... AF9: ='Tenant Info'!S9 | AI9: ='Tenant Info'!H9 | AJ9: ='Tenant Info'!T9 | AK9: ='Tenant Info'!U9 | AL9: ='Tenant Info'!V9 | AM9: ='Tenant Info'!W9 | AN9: ='Tenant Info'!F9 | AP9: ='Tenant Info'!G9 | AR9: ='Tenant Payment info'!H9 | AS9: ='Tenant Payment info'!I9 | AT9: ='Tenant Payment info'!J9 | AU9: ='Tenant Info'!X9 | AV9: ='Tenant Info'!Y9 | AW9: ='Tenant Info'!Z9 | AX9: ='Tenant Info'!AA9 | AY9: ='Tenant Info'!AB9 | AZ9: ='Tenant Info'!AC9 | BA9: ='Tenant Info'!AD9 | BB9: ='Tenant Info'!AE9 | ... BE9: ='Tenant Info'!AH9 | BF9: ='Tenant Payment info'!U9 | BG9: ='Tenant Payment info'!V9 | BH9: ='Tenant Payment info'!M9 | BI9: ='Tenant Payment info'!P9 | BJ9: ='Tenant Payment info'!W9 | BK9: ='Tenant Payment info'!AA9 | BL9: ='Tenant Payment info'!N9 | BM9: ='Tenant Payment info'!O9 | BN9: ='Tenant Payment info'!S9 | BO9: ='Tenant Payment info'!Q9 | BP9: ='Tenant Payment info'!R9 | BQ9: ='Tenant Payment info'!T9 | BR9: ='Tenant Payment info'!X9 | BS9: ='Tenant Payment info'!Y9 | BT9: ='Tenant Payment info'!Z9 | BX9: =PromotionsDiscounts!D9 | BY9: =PromotionsDiscounts!E9 | BZ9: =PromotionsDiscounts!F9 | CA9: =PromotionsDiscounts!G9 | CB9: =PromotionsDiscounts!H9 | CC9: =PromotionsDiscounts!I9 | CD9: =PromotionsDiscounts!J9 | CE9: =PromotionsDiscounts!K9 | CF9: ='Tenants Military Information'!F9 | CG9: ='Tenants Military Information'!G9 | CH9: ='Tenants Military Information'!H9 | CI9: ='Tenants Military Information'!I9 | CJ9: ='Tenants Military Information'!J9 | CK9: ='Tenants Military Information'!K9 | CL9: ='Tenants Military Information'!L9 | CM9: ='Tenants Military Information'!M9 | ... CV9: ='Tenants Military Information'!V9 | CW9: ='Tenants Lien Holder Information'!E9 | CX9: ='Tenants Lien Holder Information'!F9 | CY9: ='Tenants Lien Holder Information'!G9 | CZ9: ='Tenants Lien Holder Information'!H9 | DA9: ='Tenants Lien Holder Information'!I9 | DB9: ='Tenants Lien Holder Information'!J9 | DC9: ='Tenants Lien Holder Information'!K9 | DD9: ='Tenants Lien Holder Information'!L9 | DE9: ='Tenants Lien Holder Information'!M9
